Workbook
Name correctStr: "✔️Correct"
Name correctSymbol: "✔️"
Name fnDoesNotWorkStr: incorrectSymbol & " This function is not included in your version of Excel"
Name fnWorksStr: correctSymbol & " This function is included in your version of Excel"
Name helpPlaceholderStr: "Help text will appear here if your formula fails"
Name incorrectStr: "✘ Incorrect"
Name incorrectSymbol: "✘"
Name range_: Dev!$D$2
Name thresh: Dev!$D$4
Name tol: Dev!$D$3

Sheet Algorithm
B8: Implement an Algorithm in Excel
C17: x (input)
B20: i (index number) | C20: ri
B21: 0 | C21: r0 (initial guess) | F21: Formula text
B22: 1 | C22: r1 | F22: =IFERROR(_xlfn.FORMULATEXT(D22), "")
B23: 2 | C23: r2 | F23: =IFERROR(_xlfn.FORMULATEXT(D23), "")
B24: 3 | C24: r3 | F24: =IFERROR(_xlfn.FORMULATEXT(D24), "")
B25: 4 | C25: r4 | F25: =IFERROR(_xlfn.FORMULATEXT(D25), "")
B26: 5 | C26: r5 | F26: =IFERROR(_xlfn.FORMULATEXT(D26), "")
B27: 6 | C27: r6 | F27: =IFERROR(_xlfn.FORMULATEXT(D27), "")
B28: 7 | C28: r7 | F28: =IFERROR(_xlfn.FORMULATEXT(D28), "")
B29: 8 | C29: r8 | F29: =IFERROR(_xlfn.FORMULATEXT(D29), "")
B30: 9 | C30: r9 | F30: =IFERROR(_xlfn.FORMULATEXT(D30), "")
B31: 10 | C31: r10 | F31: =IFERROR(_xlfn.FORMULATEXT(D31), "")
B32: 11 | C32: r11 | F32: =IFERROR(_xlfn.FORMULATEXT(D32), "")
B33: 12 | C33: r12 | F33: =IFERROR(_xlfn.FORMULATEXT(D33), "")
... B41: 20 | C41: r20 (final output) | F41: =IFERROR(_xlfn.FORMULATEXT(D41), "")

Sheet Formula help
A2: =" "
B9: Relative cell references
B12: We can reference a cell value in an Excel formula by typing the address of that cell.
B14: ="Click in cell " & ADDRESS(ROW($D$19), COLUMN($D$19), 4) & " and type this formula:" -> Click in cell D19 and type this formula:
B16: ="=" & ADDRESS(ROW($B$18), COLUMN($B$18), 4) -> =B18
B18: TEST 1
B19: TEST 2 | E19: =" " & IFERROR(_xlfn.FORMULATEXT(D19), "")
B20: TEST 3 | E20: =" " & IFERROR(_xlfn.FORMULATEXT(D20), "")
E21: =" " & IFERROR(_xlfn.FORMULATEXT(D21), "")
B24: ="Cell " & ADDRESS(ROW($D$19), COLUMN($D$19), 4) & " now references the value of cell " & ADDRESS(ROW($B$18), COLUMN($B$18), 4) & "." -> Cell D19 now references the value of cell B18.
B26: Note that the referencing cell does not need to be in the same row or column as the referenced cell.
B28: ="Try changing the contents of cell " & ADDRESS(ROW($B$18), COLUMN($B$18), 4) & ". Notice that cell " & ADDRESS(ROW($D$19), COLUMN($D$19), 4) & " updates to reflect the changes." -> Try changing the contents of cell B18. Notice that cell D19 updates to reflect the changes.
B30: ="Copy (Ctrl + C) the entire cell " & ADDRESS(ROW($D$19), COLUMN($D$19), 4) & " to the clipboard, then paste (Ctrl + V) to cells " & ADDRESS(ROW($D$20), COLUMN($D$20), 4) & " and " & ADDRESS(ROW($D$21), COLUMN($D$21), 4) & ". Notice that the cell formula is different in the pasted cells." -> Copy (Ctrl + C) the entire cell D19 to the clipboard, then paste (Ctrl + V) to cells D20 and D21. Notice that the cell formula is different in the pasted cells.
B32: ="Cell " & ADDRESS(ROW($B$18), COLUMN($B$18), 4) & " is one cell above and two cells to the left of cell " & ADDRESS(ROW($D$19), COLUMN($D$19), 4) & ". The formula in cell " & ADDRESS(ROW($D$19), COLUMN($D$19), 4) & " is " & """=" & ADDRESS(ROW($B$18), COLUMN($B$18), 4) & """." -> Cell B18 is one cell above and two cells to the left of cell D19. The formula in cell D19 is "=B18".
B34: ="The formula in cell " & ADDRESS(ROW($D$19), COLUMN($D$19), 4) & " is " & """=" & ADDRESS(ROW($B$18), COLUMN($B$18), 4) & """. When we copied cell " & ADDRESS(ROW($D$19), COLUMN($D$19), 4) & " down to " & ADDRESS(ROW($D$19) + 1, COLUMN($D$19), 4) & ", the formula in " & ADDRESS(ROW($D$19) + 1, COLUMN($D$19), 4) & " was not ""=" & ADDRESS(ROW($B$18), COLUMN($B$18), 4) & """, but instead became ""=" & ADDRESS(ROW($B$18) + 1, COLUMN($B$18), 4) & """. The new formula continued to point to the address one cell above it and two cells to its left. This is known as a relative cell reference" -> The formula in cell D19 is "=B18". When we copied cell D19 down to D20, the formula in D20 was not "=B18", but instead became "=B19". The new formula continued to point to the address one cell above it and two cells to its left. This is known as a relative cell reference
B37: A relative cell reference can be thought of as "relative driving directions" rather than an exact cell address. In the previous example, the driving directions are "up 1, left 2".
B39: Follow the instructions below to observe the behaviour of relative cell references.
E43: North-west | F43: North | G43: North-east
E44: West | F44: Central | G44: East
E45: South-west | F45: South | G45: South-east
B64: Absolute cell references
B67: Excel gives us the option to lock a cell reference. A locked cell reference does not change when the formula cell is copied and pasted. This is called an absolute cell reference.
B69: We can lock a cell reference by putting the $ symbol before the row, the column, or both.
B71: =A1 | C71: Relative column, relative row | E71: Neither column A nor row 1 is locked
B72: =$A1 | C72: Absolute column, relative row | E72: Column A is locked; row 1 is not locked
B73: =A$1 | C73: Relative column, absolute row | E73: Column A is not locked; row 1 is locked
B74: =$A$1 | C74: Absolute column, absolute row | E74: Both column A and row 1 are locked
B78: Experiment with the four types of cell referencing in the space below.
B80: ="For example, in cell " & ADDRESS(ROW($B$87), COLUMN($B$87), 4) & ", enter the formula """ & $B$84 & """ and copy that formula to the other 8 cells in the grid." -> For example, in cell B87, enter the formula "=E43" and copy that formula to the other 8 cells in the grid.
B82: Before you copy each formula, predict what the output will look like.
B84: ="=" & ADDRESS(ROW($E$43), COLUMN($E$43), 4) -> =E43 | F84: ="=" & ADDRESS(ROW($E$43), COLUMN($E$43), 3) -> =$E43
B85: Relative column, relative row | F85: Absolute column, relative row
B92: ="=" & ADDRESS(ROW($E$43), COLUMN($E$43), 2) -> =E$43 | F92: ="=" & ADDRESS(ROW($E$43), COLUMN($E$43), 1) -> =$E$43
B93: Relative column, absolute row | F93: Absolute column, absolute row
B102: Further reading
B105: Switch between relative and absolute references (Microsoft.com)
B109: Mathematical operators
B112: In this activity, you will need to use mathematical operators in an Excel formula.
B115: `+` performs addition
B117: =number1 + number2
...

Sheet Dev
C2: range | D2: =MAX($D$7:$D$27) - MIN($D$7:$D$27) -> 0 | F2: y0 | G2: =MIN($D$7:$D$27) - range_ * 0.2 -> 0
C3: tol | D3: 0.05 | F3: y1 | G3: =MAX($D$7:$D$27) + range_ * 0.2 -> 0
C4: thresh | D4: =range_ * tol -> 0
B6: x label | C6: i | D6: r_i | E6: abs | F6: log10 | G6: rounded | H6: label text | I6: label (inc. line breaks)
B7: r0 | C7: 0 | D7: =Algorithm!D21 -> 0 | E7: =ABS(D7) -> 0 | F7: =_xlfn.FLOOR.MATH(LOG10(E7), 1) -> #NUM! | G7: =ROUND(D7 / 10 ^ F7, 2) * 10 ^ F7 -> #NUM! | H7: =TEXT(G7, IF(F7 >= 2, "#,#;–#,#", "#,#0." & REPT("0", 2 - F7) & ";–#,#0." & REPT("0", 2 - F7))) -> #NUM! | I7: {=IFERROR(_xlfn.IFS( G8 > G7, CHAR(10) & CHAR(10) & H7, G8 < G7, H7 & CHAR(10) & CHAR(10), TRUE, " " & H7 ), "")}
B8: r1 | C8: 1 | D8: =Algorithm!D22 -> 0 | E8: =ABS(D8) -> 0 | F8: =_xlfn.FLOOR.MATH(LOG10(E8), 1) -> #NUM! | G8: =ROUND(D8 / 10 ^ F8, 2) * 10 ^ F8 -> #NUM! | H8: =TEXT(G8, IF(F8 >= 2, "#,#;–#,#", "#,#0." & REPT("0", 2 - F8) & ";–#,#0." & REPT("0", 2 - F8))) -> #NUM! | I8: {=IFERROR(_xlfn.IFS( AND(G9 - G8 > thresh, G7 - G8 > thresh), CHAR(10) & CHAR(10) & H8, AND(G8 - G9 > thresh, G8 - G7 > thresh), H8 & CHAR(10) & CHAR(10), ABS(G8 - G7) <= thresh, IF(MOD(ROW(), 2) = 0, CHAR(10) & CHAR(10) & H8, H8 & CHAR(10) & CHAR(10)), TRUE, " " & H8 ), "")}
B9: r2 | C9: 2 | D9: =Algorithm!D23 -> 0 | E9: =ABS(D9) -> 0 | F9: =_xlfn.FLOOR.MATH(LOG10(E9), 1) -> #NUM! | G9: =ROUND(D9 / 10 ^ F9, 2) * 10 ^ F9 -> #NUM! | H9: =TEXT(G9, IF(F9 >= 2, "#,#;–#,#", "#,#0." & REPT("0", 2 - F9) & ";–#,#0." & REPT("0", 2 - F9))) -> #NUM! | I9: {=IFERROR(_xlfn.IFS( AND(G10 - G9 > thresh, G8 - G9 > thresh), CHAR(10) & CHAR(10) & H9, AND(G9 - G10 > thresh, G9 - G8 > thresh), H9 & CHAR(10) & CHAR(10), ABS(G9 - G8) <= thresh, IF(MOD(ROW(), 2) = 0, CHAR(10) & CHAR(10) & H9, H9 & CHAR(10) & CHAR(10)), TRUE, " " & H9 ), "")}
B10: r3 | C10: 3 | D10: =Algorithm!D24 -> 0 | E10: =ABS(D10) -> 0 | F10: =_xlfn.FLOOR.MATH(LOG10(E10), 1) -> #NUM! | G10: =ROUND(D10 / 10 ^ F10, 2) * 10 ^ F10 -> #NUM! | H10: =TEXT(G10, IF(F10 >= 2, "#,#;–#,#", "#,#0." & REPT("0", 2 - F10) & ";–#,#0." & REPT("0", 2 - F10))) -> #NUM! | I10: {=IFERROR(_xlfn.IFS( AND(G11 - G10 > thresh, G9 - G10 > thresh), CHAR(10) & CHAR(10) & H10, AND(G10 - G11 > thresh, G10 - G9 > thresh), H10 & CHAR(10) & CHAR(10), ABS(G10 - G9) <= thresh, IF(MOD(ROW(), 2) = 0, CHAR(10) & CHAR(10) & H10, H10 & CHAR(10) & CHAR(10)), TRUE, " " & H10 ), "")}
B11: r4 | C11: 4 | D11: =Algorithm!D25 -> 0 | E11: =ABS(D11) -> 0 | F11: =_xlfn.FLOOR.MATH(LOG10(E11), 1) -> #NUM! | G11: =ROUND(D11 / 10 ^ F11, 2) * 10 ^ F11 -> #NUM! | H11: =TEXT(G11, IF(F11 >= 2, "#,#;–#,#", "#,#0." & REPT("0", 2 - F11) & ";–#,#0." & REPT("0", 2 - F11))) -> #NUM! | I11: {=IFERROR(_xlfn.IFS( AND(G12 - G11 > thresh, G10 - G11 > thresh), CHAR(10) & CHAR(10) & H11, AND(G11 - G12 > thresh, G11 - G10 > thresh), H11 & CHAR(10) & CHAR(10), ABS(G11 - G10) <= thresh, IF(MOD(ROW(), 2) = 0, CHAR(10) & CHAR(10) & H11, H11 & CHAR(10) & CHAR(10)), TRUE, " " & H11 ), "")}
B12: r5 | C12: 5 | D12: =Algorithm!D26 -> 0 | E12: =ABS(D12) -> 0 | F12: =_xlfn.FLOOR.MATH(LOG10(E12), 1) -> #NUM! | G12: =ROUND(D12 / 10 ^ F12, 2) * 10 ^ F12 -> #NUM! | H12: =TEXT(G12, IF(F12 >= 2, "#,#;–#,#", "#,#0." & REPT("0", 2 - F12) & ";–#,#0." & REPT("0", 2 - F12))) -> #NUM! | I12: {=IFERROR(_xlfn.IFS( AND(G13 - G12 > thresh, G11 - G12 > thresh), CHAR(10) & CHAR(10) & H12, AND(G12 - G13 > thresh, G12 - G11 > thresh), H12 & CHAR(10) & CHAR(10), ABS(G12 - G11) <= thresh, IF(MOD(ROW(), 2) = 0, CHAR(10) & CHAR(10) & H12, H12 & CHAR(10) & CHAR(10)), TRUE, " " & H12 ), "")}
B13: r6 | C13: 6 | D13: =Algorithm!D27 -> 0 | E13: =ABS(D13) -> 0 | F13: =_xlfn.FLOOR.MATH(LOG10(E13), 1) -> #NUM! | G13: =ROUND(D13 / 10 ^ F13, 2) * 10 ^ F13 -> #NUM! | H13: =TEXT(G13, IF(F13 >= 2, "#,#;–#,#", "#,#0." & REPT("0", 2 - F13) & ";–#,#0." & REPT("0", 2 - F13))) -> #NUM! | I13: {=IFERROR(_xlfn.IFS( AND(G14 - G13 > thresh, G12 - G13 > thresh), CHAR(10) & CHAR(10) & H13, AND(G13 - G14 > thresh, G13 - G12 > thresh), H13 & CHAR(10) & CHAR(10), ABS(G13 - G12) <= thresh, IF(MOD(ROW(), 2) = 0, CHAR(10) & CHAR(10) & H13, H13 & CHAR(10) & CHAR(10)), TRUE, " " & H13 ), "")}
B14: r7 | C14: 7 | D14: =Algorithm!D28 -> 0 | E14: =ABS(D14) -> 0 | F14: =_xlfn.FLOOR.MATH(LOG10(E14), 1) -> #NUM! | G14: =ROUND(D14 / 10 ^ F14, 2) * 10 ^ F14 -> #NUM! | H14: =TEXT(G14, IF(F14 >= 2, "#,#;–#,#", "#,#0." & REPT("0", 2 - F14) & ";–#,#0." & REPT("0", 2 - F14))) -> #NUM! | I14: {=IFERROR(_xlfn.IFS( AND(G15 - G14 > thresh, G13 - G14 > thresh), CHAR(10) & CHAR(10) & H14, AND(G14 - G15 > thresh, G14 - G13 > thresh), H14 & CHAR(10) & CHAR(10), ABS(G14 - G13) <= thresh, IF(MOD(ROW(), 2) = 0, CHAR(10) & CHAR(10) & H14, H14 & CHAR(10) & CHAR(10)), TRUE, " " & H14 ), "")}
B15: r8 | C15: 8 | D15: =Algorithm!D29 -> 0 | E15: =ABS(D15) -> 0 | F15: =_xlfn.FLOOR.MATH(LOG10(E15), 1) -> #NUM! | G15: =ROUND(D15 / 10 ^ F15, 2) * 10 ^ F15 -> #NUM! | H15: =TEXT(G15, IF(F15 >= 2, "#,#;–#,#", "#,#0." & REPT("0", 2 - F15) & ";–#,#0." & REPT("0", 2 - F15))) -> #NUM! | I15: {=IFERROR(_xlfn.IFS( AND(G16 - G15 > thresh, G14 - G15 > thresh), CHAR(10) & CHAR(10) & H15, AND(G15 - G16 > thresh, G15 - G14 > thresh), H15 & CHAR(10) & CHAR(10), ABS(G15 - G14) <= thresh, IF(MOD(ROW(), 2) = 0, CHAR(10) & CHAR(10) & H15, H15 & CHAR(10) & CHAR(10)), TRUE, " " & H15 ), "")}
B16: r9 | C16: 9 | D16: =Algorithm!D30 -> 0 | E16: =ABS(D16) -> 0 | F16: =_xlfn.FLOOR.MATH(LOG10(E16), 1) -> #NUM! | G16: =ROUND(D16 / 10 ^ F16, 2) * 10 ^ F16 -> #NUM! | H16: =TEXT(G16, IF(F16 >= 2, "#,#;–#,#", "#,#0." & REPT("0", 2 - F16) & ";–#,#0." & REPT("0", 2 - F16))) -> #NUM! | I16: {=IFERROR(_xlfn.IFS( AND(G17 - G16 > thresh, G15 - G16 > thresh), CHAR(10) & CHAR(10) & H16, AND(G16 - G17 > thresh, G16 - G15 > thresh), H16 & CHAR(10) & CHAR(10), ABS(G16 - G15) <= thresh, IF(MOD(ROW(), 2) = 0, CHAR(10) & CHAR(10) & H16, H16 & CHAR(10) & CHAR(10)), TRUE, " " & H16 ), "")}
B17: r10 | C17: 10 | D17: =Algorithm!D31 -> 0 | E17: =ABS(D17) -> 0 | F17: =_xlfn.FLOOR.MATH(LOG10(E17), 1) -> #NUM! | G17: =ROUND(D17 / 10 ^ F17, 2) * 10 ^ F17 -> #NUM! | H17: =TEXT(G17, IF(F17 >= 2, "#,#;–#,#", "#,#0." & REPT("0", 2 - F17) & ";–#,#0." & REPT("0", 2 - F17))) -> #NUM! | I17: {=IFERROR(_xlfn.IFS( AND(G18 - G17 > thresh, G16 - G17 > thresh), CHAR(10) & CHAR(10) & H17, AND(G17 - G18 > thresh, G17 - G16 > thresh), H17 & CHAR(10) & CHAR(10), ABS(G17 - G16) <= thresh, IF(MOD(ROW(), 2) = 0, CHAR(10) & CHAR(10) & H17, H17 & CHAR(10) & CHAR(10)), TRUE, " " & H17 ), "")}
B18: r11 | C18: 11 | D18: =Algorithm!D32 -> 0 | E18: =ABS(D18) -> 0 | F18: =_xlfn.FLOOR.MATH(LOG10(E18), 1) -> #NUM! | G18: =ROUND(D18 / 10 ^ F18, 2) * 10 ^ F18 -> #NUM! | H18: =TEXT(G18, IF(F18 >= 2, "#,#;–#,#", "#,#0." & REPT("0", 2 - F18) & ";–#,#0." & REPT("0", 2 - F18))) -> #NUM! | I18: {=IFERROR(_xlfn.IFS( AND(G19 - G18 > thresh, G17 - G18 > thresh), CHAR(10) & CHAR(10) & H18, AND(G18 - G19 > thresh, G18 - G17 > thresh), H18 & CHAR(10) & CHAR(10), ABS(G18 - G17) <= thresh, IF(MOD(ROW(), 2) = 0, CHAR(10) & CHAR(10) & H18, H18 & CHAR(10) & CHAR(10)), TRUE, " " & H18 ), "")}
B19: r12 | C19: 12 | D19: =Algorithm!D33 -> 0 | E19: =ABS(D19) -> 0 | F19: =_xlfn.FLOOR.MATH(LOG10(E19), 1) -> #NUM! | G19: =ROUND(D19 / 10 ^ F19, 2) * 10 ^ F19 -> #NUM! | H19: =TEXT(G19, IF(F19 >= 2, "#,#;–#,#", "#,#0." & REPT("0", 2 - F19) & ";–#,#0." & REPT("0", 2 - F19))) -> #NUM! | I19: {=IFERROR(_xlfn.IFS( AND(G20 - G19 > thresh, G18 - G19 > thresh), CHAR(10) & CHAR(10) & H19, AND(G19 - G20 > thresh, G19 - G18 > thresh), H19 & CHAR(10) & CHAR(10), ABS(G19 - G18) <= thresh, IF(MOD(ROW(), 2) = 0, CHAR(10) & CHAR(10) & H19, H19 & CHAR(10) & CHAR(10)), TRUE, " " & H19 ), "")}
... B26: r19 | C26: 19 | D26: =Algorithm!D40 -> 0 | E26: =ABS(D26) -> 0 | F26: =_xlfn.FLOOR.MATH(LOG10(E26), 1) -> #NUM! | G26: =ROUND(D26 / 10 ^ F26, 2) * 10 ^ F26 -> #NUM! | H26: =TEXT(G26, IF(F26 >= 2, "#,#;–#,#", "#,#0." & REPT("0", 2 - F26) & ";–#,#0." & REPT("0", 2 - F26))) -> #NUM! | I26: {=IFERROR(_xlfn.IFS( AND(G27 - G26 > thresh, G25 - G26 > thresh), CHAR(10) & CHAR(10) & H26, AND(G26 - G27 > thresh, G26 - G25 > thresh), H26 & CHAR(10) & CHAR(10), ABS(G26 - G25) <= thresh, IF(MOD(ROW(), 2) = 0, CHAR(10) & CHAR(10) & H26, H26 & CHAR(10) & CHAR(10)), TRUE, " " & H26 ), "")}
B27: r20 | C27: 20 | D27: =Algorithm!D41 -> 0 | E27: =ABS(D27) -> 0 | F27: =_xlfn.FLOOR.MATH(LOG10(E27), 1) -> #NUM! | G27: =ROUND(D27 / 10 ^ F27, 2) * 10 ^ F27 -> #NUM! | H27: =TEXT(G27, IF(F27 >= 2, "#,#;–#,#", "#,#0." & REPT("0", 2 - F27) & ";–#,#0." & REPT("0", 2 - F27))) -> #NUM! | I27: {=IFERROR(_xlfn.IFS( G26 > G27, CHAR(10) & CHAR(10) & H27, G26 < G27, H27 & CHAR(10) & CHAR(10), TRUE, " " & H27 ), "")}
B30: SHAPE LABELS--DO NOT DELETE
B31: Relative and absolute cell references
B32: ="1. In cell " & ADDRESS(ROW('Formula help'!$E$49), COLUMN('Formula help'!$E$49), 4, 1) & ", enter the formula:" & CHAR(10) & "=" & ADDRESS(ROW('Formula help'!$E$43), COLUMN('Formula help'!$E$43), 4, 1) -> 1. In cell E49, enter the formula: =E43
B33: ="2. Copy the formula down to cell " & ADDRESS(ROW('Formula help'!$E$45), COLUMN('Formula help'!$E$45), 4, 1) & "." -> 2. Copy the formula down to cell E45.
B34: ="3. Copy the formula across to cell " & ADDRESS(ROW('Formula help'!$G$45), COLUMN('Formula help'!$G$45), 4, 1) & "." -> 3. Copy the formula across to cell G45.
